[2025-02-04T07:49:39.685+0000] {taskinstance.py:1103} INFO - Dependencies all met for dep_context=non-requeueable deps ti=<TaskInstance: transform_dag.transform_task manual__2025-02-04T07:49:37.912790+00:00 [queued]>
[2025-02-04T07:49:39.690+0000] {taskinstance.py:1103} INFO - Dependencies all met for dep_context=requeueable deps ti=<TaskInstance: transform_dag.transform_task manual__2025-02-04T07:49:37.912790+00:00 [queued]>
[2025-02-04T07:49:39.690+0000] {taskinstance.py:1308} INFO - Starting attempt 1 of 1
[2025-02-04T07:49:39.699+0000] {taskinstance.py:1327} INFO - Executing <Task(PythonOperator): transform_task> on 2025-02-04 07:49:37.912790+00:00
[2025-02-04T07:49:39.703+0000] {standard_task_runner.py:57} INFO - Started process 7563 to run task
[2025-02-04T07:49:39.705+0000] {standard_task_runner.py:84} INFO - Running: ['airflow', 'tasks', 'run', 'transform_dag', 'transform_task', 'manual__2025-02-04T07:49:37.912790+00:00', '--job-id', '13', '--raw', '--subdir', 'DAGS_FOLDER/transform_dag.py', '--cfg-path', '/tmp/tmpnrx3kg0w']
[2025-02-04T07:49:39.705+0000] {standard_task_runner.py:85} INFO - Job 13: Subtask transform_task
[2025-02-04T07:49:39.729+0000] {task_command.py:410} INFO - Running <TaskInstance: transform_dag.transform_task manual__2025-02-04T07:49:37.912790+00:00 [running]> on host codespaces-039a13
[2025-02-04T07:49:39.765+0000] {taskinstance.py:1545} INFO - Exporting env vars: AIRFLOW_CTX_DAG_OWNER='airflow' AIRFLOW_CTX_DAG_ID='transform_dag' AIRFLOW_CTX_TASK_ID='transform_task' AIRFLOW_CTX_EXECUTION_DATE='2025-02-04T07:49:37.912790+00:00' AIRFLOW_CTX_TRY_NUMBER='1' AIRFLOW_CTX_DAG_RUN_ID='manual__2025-02-04T07:49:37.912790+00:00'
[2025-02-04T07:49:39.765+0000] {taskinstance.py:1824} ERROR - Task failed with exception
Traceback (most recent call last):
  File "/home/vscode/.local/lib/python3.10/site-packages/airflow/operators/python.py", line 181, in execute
    return_value = self.execute_callable()
  File "/home/vscode/.local/lib/python3.10/site-packages/airflow/operators/python.py", line 198, in execute_callable
    return self.python_callable(*self.op_args, **self.op_kwargs)
  File "/workspaces/hands-on-introduction-data-engineering-4395021/airflow/dags/transform_dag.py", line 15, in transform_data
    today= date.today()
NameError: name 'date' is not defined
[2025-02-04T07:49:39.768+0000] {taskinstance.py:1345} INFO - Marking task as FAILED. dag_id=transform_dag, task_id=transform_task, execution_date=20250204T074937, start_date=20250204T074939, end_date=20250204T074939
[2025-02-04T07:49:39.776+0000] {standard_task_runner.py:104} ERROR - Failed to execute job 13 for task transform_task (name 'date' is not defined; 7563)
[2025-02-04T07:49:39.797+0000] {local_task_job_runner.py:225} INFO - Task exited with return code 1
[2025-02-04T07:49:39.805+0000] {taskinstance.py:2653} INFO - 0 downstream tasks scheduled from follow-on schedule check
