[2025-02-06T18:54:59.587+0000] {taskinstance.py:1103} INFO - Dependencies all met for dep_context=non-requeueable deps ti=<TaskInstance: transform_SnP.transform_SnP_task manual__2025-02-06T18:54:56.543527+00:00 [queued]>
[2025-02-06T18:54:59.591+0000] {taskinstance.py:1103} INFO - Dependencies all met for dep_context=requeueable deps ti=<TaskInstance: transform_SnP.transform_SnP_task manual__2025-02-06T18:54:56.543527+00:00 [queued]>
[2025-02-06T18:54:59.592+0000] {taskinstance.py:1308} INFO - Starting attempt 1 of 1
[2025-02-06T18:54:59.601+0000] {taskinstance.py:1327} INFO - Executing <Task(PythonOperator): transform_SnP_task> on 2025-02-06 18:54:56.543527+00:00
[2025-02-06T18:54:59.605+0000] {standard_task_runner.py:57} INFO - Started process 19605 to run task
[2025-02-06T18:54:59.607+0000] {standard_task_runner.py:84} INFO - Running: ['airflow', 'tasks', 'run', 'transform_SnP', 'transform_SnP_task', 'manual__2025-02-06T18:54:56.543527+00:00', '--job-id', '26', '--raw', '--subdir', 'DAGS_FOLDER/transform-snp-dag.py', '--cfg-path', '/tmp/tmp86ov5czn']
[2025-02-06T18:54:59.607+0000] {standard_task_runner.py:85} INFO - Job 26: Subtask transform_SnP_task
[2025-02-06T18:54:59.637+0000] {task_command.py:410} INFO - Running <TaskInstance: transform_SnP.transform_SnP_task manual__2025-02-06T18:54:56.543527+00:00 [running]> on host codespaces-039a13
[2025-02-06T18:54:59.676+0000] {taskinstance.py:1545} INFO - Exporting env vars: AIRFLOW_CTX_DAG_OWNER='airflow' AIRFLOW_CTX_DAG_ID='transform_SnP' AIRFLOW_CTX_TASK_ID='transform_SnP_task' AIRFLOW_CTX_EXECUTION_DATE='2025-02-06T18:54:56.543527+00:00' AIRFLOW_CTX_TRY_NUMBER='1' AIRFLOW_CTX_DAG_RUN_ID='manual__2025-02-06T18:54:56.543527+00:00'
[2025-02-06T18:54:59.678+0000] {taskinstance.py:1824} ERROR - Task failed with exception
Traceback (most recent call last):
  File "/home/vscode/.local/lib/python3.10/site-packages/airflow/operators/python.py", line 181, in execute
    return_value = self.execute_callable()
  File "/home/vscode/.local/lib/python3.10/site-packages/airflow/operators/python.py", line 198, in execute_callable
    return self.python_callable(*self.op_args, **self.op_kwargs)
  File "/workspaces/hands-on-introduction-data-engineering-4395021/airflow/dags/transform-snp-dag.py", line 15, in transform_data
    df = pd.read_csv('manual-snp-extract.csv',header=0)
  File "/home/vscode/.local/lib/python3.10/site-packages/pandas/io/parsers/readers.py", line 1026, in read_csv
    return _read(filepath_or_buffer, kwds)
  File "/home/vscode/.local/lib/python3.10/site-packages/pandas/io/parsers/readers.py", line 620, in _read
    parser = TextFileReader(filepath_or_buffer, **kwds)
  File "/home/vscode/.local/lib/python3.10/site-packages/pandas/io/parsers/readers.py", line 1620, in __init__
    self._engine = self._make_engine(f, self.engine)
  File "/home/vscode/.local/lib/python3.10/site-packages/pandas/io/parsers/readers.py", line 1880, in _make_engine
    self.handles = get_handle(
  File "/home/vscode/.local/lib/python3.10/site-packages/pandas/io/common.py", line 873, in get_handle
    handle = open(
FileNotFoundError: [Errno 2] No such file or directory: 'manual-snp-extract.csv'
[2025-02-06T18:54:59.683+0000] {taskinstance.py:1345} INFO - Marking task as FAILED. dag_id=transform_SnP, task_id=transform_SnP_task, execution_date=20250206T185456, start_date=20250206T185459, end_date=20250206T185459
[2025-02-06T18:54:59.690+0000] {standard_task_runner.py:104} ERROR - Failed to execute job 26 for task transform_SnP_task ([Errno 2] No such file or directory: 'manual-snp-extract.csv'; 19605)
[2025-02-06T18:54:59.699+0000] {local_task_job_runner.py:225} INFO - Task exited with return code 1
[2025-02-06T18:54:59.709+0000] {taskinstance.py:2653} INFO - 0 downstream tasks scheduled from follow-on schedule check
